Workbook

Sheet Массив данных
A1: СРЕДНИЕ ГОДОВЫЕ (Н ср) И МАКСИМАЛЬНЫЕ (Н макс) УРОВНИ ВОДЫ ПО ОГП ВОЛГОГРАДСКОГО ВДХР (1986-2018), см. граф.постов
A3: Пор. № | B3: Год | C3: Балаково, ГЭС, н/б | E3: Вольск | G3: Маркс | I3: Саратов | K3: Ровное | M3: Камышин | O3: Дубовка | Q3: Волжский
C4: Н ср | D4: Н макс | E4: Н ср | F4: Н макс | G4: Н ср | H4: Н макс | I4: Н ср | J4: Н макс | K4: Н ср | L4: Н макс | M4: Н ср | N4: Н макс | O4: Н ср | P4: Н макс | Q4: Н ср | R4: Н макс
A6: 1 | B6: 1986 | C6: 694 | D6: 1138 | E6: 636 | F6: 1022 | G6: 529 | H6: 792 | I6: 469 | J6: 624 | K6: 439 | L6: 534 | M6: 435 | N6: 528 | O6: 432 | P6: 522 | Q6: 431 | R6: 529
A7: =A6+1 -> 2 | B7: =B6+1 -> 1987 | C7: 695 | D7: 1098 | E7: 636 | F7: 995 | G7: 534 | H7: 774 | I7: 480 | J7: 631 | K7: 451 | L7: 538 | M7: 447 | N7: 527 | O7: 443 | P7: 530 | Q7: 439 | R7: 532
A8: =A7+1 -> 3 | B8: =B7+1 -> 1988 | M8: 445 | N8: 520 | O8: 442 | P8: 519 | Q8: 439 | R8: 517
A9: =A8+1 -> 4 | B9: =B8+1 -> 1989 | C9: 588 | D9: 1093 | E9: 566 | F9: 1002 | G9: 483 | H9: 750 | I9: 456 | J9: 577 | K9: 437 | L9: 522 | M9: 436 | N9: 523 | O9: 432 | P9: 517 | Q9: 430 | R9: 516
A10: =A9+1 -> 5 | B10: =B9+1 -> 1990 | C10: 709 | D10: 1094 | E10: 675 | F10: 992 | G10: 573 | H10: 770 | I10: 516 | J10: 600 | K10: 486 | L10: 531 | M10: 478 | N10: 519 | O10: 473 | P10: 517 | Q10: 473 | R10: 519
A11: =A10+1 -> 6 | B11: =B10+1 -> 1991 | C11: 709 | D11: 1257 | E11: 670 | F11: 1155 | G11: 568 | H11: 878 | I11: 509 | J11: 703 | K11: 479 | L11: 604 | M11: 471 | N11: 565 | O11: 467 | P11: 563 | Q11: 465 | R11: 560
A12: =A11+1 -> 7 | B12: =B11+1 -> 1992 | C12: 655 | D12: 1061 | E12: 626 | F12: 979 | G12: 540 | H12: 760 | I12: 498 | J12: 603 | K12: 477 | L12: 521 | M12: 471 | N12: 514 | O12: 470 | P12: 514 | Q12: 467 | R12: 511
A13: =A12+1 -> 8 | B13: =B12+1 -> 1993 | C13: 671 | D13: 1055 | E13: 644 | F13: 970 | G13: 543 | H13: 750 | I13: 494 | J13: 589 | K13: 469 | L13: 522 | M13: 463 | N13: 510 | O13: 459 | P13: 512 | Q13: 458 | R13: 510
A14: =A13+1 -> 9 | B14: =B13+1 -> 1994 | C14: 738 | D14: 1170 | E14: 690 | F14: 1033 | G14: 571 | H14: 784 | I14: 509 | J14: 606 | K14: 474 | L14: 534 | M14: 461 | N14: 513 | O14: 458 | P14: 513 | Q14: 457 | R14: 510
A15: =A14+1 -> 10 | B15: =B14+1 -> 1995 | C15: 671 | D15: 1193 | E15: 637 | F15: 1072 | G15: 554 | H15: 832 | I15: 505 | J15: 656 | K15: 481 | L15: 558 | M15: 470 | N15: 518 | O15: 469 | P15: 527 | Q15: 469 | R15: 527
A16: =A15+1 -> 11 | B16: =B15+1 -> 1996 | C16: 560 | D16: 965 | E16: 537 | F16: 844 | G16: 487 | H16: 674 | I16: 463 | J16: 547 | K16: 454 | L16: 528 | M16: 451 | N16: 525 | O16: 452 | P16: 526 | Q16: 451 | R16: 526
A17: =A16+1 -> 12 | B17: =B16+1 -> 1997 | C17: 625 | D17: 1096 | E17: 601 | F17: 984 | G17: 531 | H17: 764 | I17: 492 | J17: 611 | K17: 473 | L17: 550 | M17: 468 | N17: 518 | O17: 466 | P17: 513 | Q17: 464 | R17: 508
A18: =A17+1 -> 13 | B18: =B17+1 -> 1998 | C18: 676 | D18: 1120 | E18: 638 | F18: 1013 | G18: 551 | H18: 782 | I18: 501 | J18: 618 | K18: 475 | L18: 539 | M18: 467 | N18: 512 | O18: 464 | P18: 506 | Q18: 461 | R18: 502
A19: =A18+1 -> 14 | B19: =B18+1 -> 1999 | C19: 684 | D19: 1099 | E19: 645 | F19: 1022 | G19: 556 | H19: 784 | I19: 502 | J19: 584 | K19: 472 | L19: 525 | M19: 464 | N19: 521 | O19: 461 | P19: 515 | Q19: 459 | R19: 513
A20: =A19+1 -> 15 | B20: =B19+1 -> 2000 | C20: 628 | D20: 1080 | E20: 600 | F20: 992 | G20: 531 | H20: 768 | I20: 498 | J20: 614 | K20: 476 | L20: 531 | M20: 476 | N20: 517 | O20: 474 | P20: 518 | Q20: 474 | R20: 518
A21: =A20+1 -> 16 | B21: =B20+1 -> 2001 | D21: 1148 | E21: 640 | F21: 1051 | G21: 580 | H21: 825 | I21: 517 | J21: 661 | K21: 492 | L21: 560 | M21: 490 | N21: 532 | O21: 485 | P21: 527 | Q21: 487 | R21: 514
A22: =A21+1 -> 17 | B22: =B21+1 -> 2002 | C22: 652 | D22: 1076 | E22: 631 | F22: 996 | G22: 554 | H22: 780 | I22: 510 | J22: 617 | K22: 485 | L22: 529 | M22: 484 | N22: 524 | O22: 481 | P22: 530 | Q22: 480 | R22: 528
A23: =A22+1 -> 18 | B23: =B22+1 -> 2003 | C23: 632 | D23: 1092 | E23: 611 | F23: 991 | G23: 552 | H23: 784 | I23: 511 | J23: 616 | K23: 492 | L23: 537 | M23: 491 | N23: 524 | O23: 486 | P23: 518 | Q23: 486 | R23: 517
A24: =A23+1 -> 19 | B24: =B23+1 -> 2004 | C24: 638 | D24: 1100 | E24: 624 | F24: 1014 | G24: 552 | H24: 784 | I24: 503 | J24: 609 | K24: 483 | L24: 532 | M24: 479 | N24: 527 | O24: 476 | P24: 528 | Q24: 478 | R24: 530
A25: =A24+1 -> 20 | B25: =B24+1 -> 2005 | C25: 668 | D25: 1166 | E25: 662 | F25: 1110 | G25: 575 | H25: 842 | I25: 519 | J25: 669 | K25: 496 | L25: 577 | M25: 488 | N25: 532 | O25: 487 | P25: 544 | Q25: 490 | R25: 537
A26: =A25+1 -> 21 | B26: =B25+1 -> 2006 | C26: 584 | D26: 985 | E26: 575 | F26: 922 | G26: 529 | H26: 726 | I26: 493 | J26: 595 | K26: 482 | L26: 550 | M26: 475 | N26: 533 | O26: 479 | P26: 529 | Q26: 480 | R26: 531
A27: =A26+1 -> 22 | B27: =B26+1 -> 2007 | C27: 666 | D27: 1095 | E27: 652 | F27: 992 | G27: 572 | H27: 786 | I27: 508 | J27: 629 | K27: 483 | L27: 541 | M27: 473 | N27: 517 | O27: 475 | P27: 521 | Q27: 475 | R27: 521
A28: =A27+1 -> 23 | B28: =B27+1 -> 2008 | C28: 606 | D28: 1116 | E28: 599 | F28: 1012 | G28: 537 | H28: 791 | I28: 495 | J28: 627 | K28: 474 | L28: 569 | M28: 469 | N28: 546 | O28: 472 | P28: 546 | Q28: 472 | R28: 549
A29: =A28+1 -> 24 | B29: =B28+1 -> 2009 | C29: 616 | D29: 1110 | E29: 606 | F29: 988 | G29: 538 | H29: 770 | I29: 493 | J29: 610 | K29: 473 | L29: 545 | M29: 468 | N29: 529 | O29: 470 | P29: 524 | Q29: 468 | R29: 524
A30: =A29+1 -> 25 | B30: =B29+1 -> 2010 | C30: 572 | D30: 1107 | E30: 548 | F30: 990 | G30: 490 | H30: 776 | I30: 454 | J30: 611 | K30: 437 | L30: 560 | M30: 433 | N30: 546 | O30: 435 | P30: 542 | Q30: 436 | R30: 530
A31: =A30+1 -> 26 | B31: =B30+1 -> 2011 | C31: 571 | D31: 1072 | E31: 547 | F31: 980 | G31: 490 | H31: 771 | I31: 456 | J31: 614 | K31: 439 | L31: 549 | M31: 436 | N31: 523 | O31: 439 | P31: 522 | Q31: 442 | R31: 528
A32: =A31+1 -> 27 | B32: =B31+1 -> 2012 | C32: 612 | D32: 1133 | E32: 582 | F32: 992 | G32: 519 | H32: 758 | I32: 483 | J32: 615 | K32: 465 | L32: 552 | M32: 460 | N32: 537 | O32: 460 | P32: 532 | Q32: 460 | R32: 532
A33: =A32+1 -> 28 | B33: =B32+1 -> 2013 | C33: 664 | D33: 1123 | E33: 621 | F33: 1016 | G33: 548 | H33: 773 | I33: 503 | J33: 593 | K33: 482 | L33: 537 | M33: 470 | N33: 520 | O33: 469 | P33: 516 | Q33: 469 | R33: 517
... A38: =A37+1 -> 33 | B38: =B37+1 -> 2018 | C38: 647 | D38: 1138 | E38: 624 | F38: 1030 | G38: 522 | H38: 766 | I38: 488 | J38: 591 | K38: 470 | L38: 520 | M38: 458 | N38: 509 | O38: 457 | P38: 513 | Q38: 458 | R38: 513
A40: Ср.многолетн.зн.: | C40: =SUM(C6:C38)/31 -> 642.58065 | D40: =SUM(D6:D38)/32 -> 1096.7188 | E40: =SUM(E6:E38)/32 -> 615.34375 | F40: =SUM(F6:F38)/32 -> 999.4375 | G40: =SUM(G6:G38)/32 -> 537.3125 | H40: =SUM(H6:H38)/32 -> 775.125 | I40: =SUM(I6:I38)/32 -> 492.90625 | J40: =SUM(J6:J38)/32 -> 612.78125 | K40: =SUM(K6:K38)/32 -> 471.15625 | L40: =SUM(L6:L38)/32 -> 541.84375 | M40: =SUM(M6:M38)/33 -> 464.30303 | N40: =SUM(N6:N38)/33 -> 524.54545 | O40: =SUM(O6:O38)/33 -> 462.93939 | P40: =SUM(P6:P38)/33 -> 524.45455 | Q40: =SUM(Q6:Q38)/33 -> 462.54545 | R40: =SUM(R6:R38)/33 -> 523.33333
A41: Ср.многолетн.макс.: | C41: =MAX(C6:C38) -> 738 | D41: =MAX(D6:D38) -> 1257 | E41: =MAX(E6:E38) -> 690 | F41: =MAX(F6:F38) -> 1155 | G41: =MAX(G6:G38) -> 580 | H41: =MAX(H6:H38) -> 878 | I41: =MAX(I6:I38) -> 519 | J41: =MAX(J6:J38) -> 703 | ... R41: =MAX(R6:R38) -> 560
B42: Год= | C42: 1994 | D42: 1991 | E42: 1994 | F42: 1991 | G42: 2001 | H42: 1991 | I42: 2005 | J42: 1991 | K42: 2005 | L42: 1991 | M42: 2003 | N42: 1991 | O42: 2005 | P42: 1991 | Q42: 2005 | R42: 1991
A43: Ср.многолетн.мин.: | C43: =MIN(C6:C38) -> 560 | D43: =MIN(D6:D38) -> 844 | E43: =MIN(E6:E38) -> 537 | F43: =MIN(F6:F38) -> 804 | G43: =MIN(G6:G38) -> 483 | H43: =MIN(H6:H38) -> 656 | I43: =MIN(I6:I38) -> 454 | J43: =MIN(J6:J38) -> 547 | ... R43: =MIN(R6:R38) -> 502
B44: Год= | C44: 1996 | D44: 2015 | E44: 1996 | F44: 2015 | G44: 1989 | H44: 2015 | I44: 2010 | J44: 2015 | K44: 1989; 2010 | L44: 2015 | M44: 2010 | N44: 2018 | O44: 1986; -89 | P44: 1998 | Q44: 1989 | R44: 1998
A46: СРЕДНИЕ ГОДОВЫЕ (Н ср) И МАКСИМАЛЬНЫЕ (Н макс) УРОВНИ ВОДЫ ПО ОГП ВОЛГОГРАДСКОГО ВДХР (1986-2018), м Абс. | T46: Восполнение недостающих данных по аналогиям
A47: С восполнением недостающих данных по аналогиям (см. Таблицу правее →)
A48: Пор. № | B48: Год | C48: Балаково, ГЭС, н/б | E48: Вольск | G48: Маркс | I48: Саратов | K48: Ровное | M48: Камышин | O48: Дубовка | Q48: Волжский | T48: Пор. № | U48: Год | V48: Балаково, ГЭС, н/б | X48: Вольск | Z48: Маркс | AB48: Саратов | AD48: Ровное | AF48: Камышин | AH48: Дубовка | AJ48: Волжский
...

Sheet Данные по участкам
A1: СРЕДНИЕ ГОДОВЫЕ (Н ср уч) И МАКСИМАЛЬНЫЕ (Н макс уч) УРОВНИ ВОДЫ НА УЧАСТКАХ ВОЛГОГРАДСКОГО ВДХР (1986-2018), м Абс.
A3: Пор. № | B3: Год | C3: Верхний участок | E3: Средний участок | G3: Нижний участок | J3: ДИАГРАММЫ:
C4: Н ср | D4: Н макс | E4: Н ср | F4: Н макс | G4: Н ср | H4: Н макс
J5: 1. Верхний (Речной) участок Волгоградского вдхр (Балаково - Маркс):
A6: 1 | B6: 1986 | C6: =IF(AND(ISNUMBER('Массив данных'!C51),ISNUMBER('Массив данных'!G51)),0.5*('Массив данных'!C51+'Массив данных'!G51),"") -> 16.115 | D6: =IF(ISNUMBER('Массив данных'!D51),'Массив данных'!D51,"") -> 21.38 | E6: =IF(AND(ISNUMBER('Массив данных'!G51),ISNUMBER('Массив данных'!K51)),0.5*('Массив данных'!G51+'Массив данных'!K51),"") -> 14.84 | F6: =IF(ISNUMBER('Массив данных'!G51),'Массив данных'!G51,"") -> 15.29 | G6: =IF(AND(ISNUMBER('Массив данных'!K51),ISNUMBER('Массив данных'!Q51)),0.5*('Массив данных'!K51+'Массив данных'!Q51),"") -> 14.35 | H6: =IF(AND(ISNUMBER('Массив данных'!L51),ISNUMBER('Массив данных'!N51),ISNUMBER('Массив данных'!P51),ISNUMBER('Массив данных'!R51)),MAX('Массив данных'!L51,'Массив данных'!N51,'Массив данных'!P51,'Массив данных'!R51),"") -> 15.34
A7: 2 | B7: 1987 | C7: =IF(AND(ISNUMBER('Массив данных'!C52),ISNUMBER('Массив данных'!G52)),0.5*('Массив данных'!C52+'Массив данных'!G52),"") -> 16.145 | D7: =IF(ISNUMBER('Массив данных'!D52),'Массив данных'!D52,"") -> 20.98 | E7: =IF(AND(ISNUMBER('Массив данных'!G52),ISNUMBER('Массив данных'!K52)),0.5*('Массив данных'!G52+'Массив данных'!K52),"") -> 14.925 | F7: =IF(ISNUMBER('Массив данных'!G52),'Массив данных'!G52,"") -> 15.34 | G7: =IF(AND(ISNUMBER('Массив данных'!K52),ISNUMBER('Массив данных'!Q52)),0.5*('Массив данных'!K52+'Массив данных'!Q52),"") -> 14.45 | H7: =IF(AND(ISNUMBER('Массив данных'!L52),ISNUMBER('Массив данных'!N52),ISNUMBER('Массив данных'!P52),ISNUMBER('Массив данных'!R52)),MAX('Массив данных'!L52,'Массив данных'!N52,'Массив данных'!P52,'Массив данных'!R52),"") -> 15.38
A8: 3 | B8: 1988 | C8: =IF(AND(ISNUMBER('Массив данных'!C53),ISNUMBER('Массив данных'!G53)),0.5*('Массив данных'!C53+'Массив данных'!G53),"") -> 15.845 | D8: =IF(ISNUMBER('Массив данных'!D53),'Массив данных'!D53,"") -> 21.71 | E8: =IF(AND(ISNUMBER('Массив данных'!G53),ISNUMBER('Массив данных'!K53)),0.5*('Массив данных'!G53+'Массив данных'!K53),"") -> 15.135 | F8: =IF(ISNUMBER('Массив данных'!G53),'Массив данных'!G53,"") -> 15.45 | G8: =IF(AND(ISNUMBER('Массив данных'!K53),ISNUMBER('Массив данных'!Q53)),0.5*('Массив данных'!K53+'Массив данных'!Q53),"") -> 14.605 | H8: =IF(AND(ISNUMBER('Массив данных'!L53),ISNUMBER('Массив данных'!N53),ISNUMBER('Массив данных'!P53),ISNUMBER('Массив данных'!R53)),MAX('Массив данных'!L53,'Массив данных'!N53,'Массив данных'!P53,'Массив данных'!R53),"") -> 15.59
A9: 4 | B9: 1989 | C9: =IF(AND(ISNUMBER('Массив данных'!C54),ISNUMBER('Массив данных'!G54)),0.5*('Массив данных'!C54+'Массив данных'!G54),"") -> 15.355 | D9: =IF(ISNUMBER('Массив данных'!D54),'Массив данных'!D54,"") -> 20.93 | E9: =IF(AND(ISNUMBER('Массив данных'!G54),ISNUMBER('Массив данных'!K54)),0.5*('Массив данных'!G54+'Массив данных'!K54),"") -> 14.6 | F9: =IF(ISNUMBER('Массив данных'!G54),'Массив данных'!G54,"") -> 14.83 | G9: =IF(AND(ISNUMBER('Массив данных'!K54),ISNUMBER('Массив данных'!Q54)),0.5*('Массив данных'!K54+'Массив данных'!Q54),"") -> 14.335 | H9: =IF(AND(ISNUMBER('Массив данных'!L54),ISNUMBER('Массив данных'!N54),ISNUMBER('Массив данных'!P54),ISNUMBER('Массив данных'!R54)),MAX('Массив данных'!L54,'Массив данных'!N54,'Массив данных'!P54,'Массив данных'!R54),"") -> 15.23
A10: 5 | B10: 1990 | C10: =IF(AND(ISNUMBER('Массив данных'!C55),ISNUMBER('Массив данных'!G55)),0.5*('Массив данных'!C55+'Массив данных'!G55),"") -> 16.41 | D10: =IF(ISNUMBER('Массив данных'!D55),'Массив данных'!D55,"") -> 20.94 | E10: =IF(AND(ISNUMBER('Массив данных'!G55),ISNUMBER('Массив данных'!K55)),0.5*('Массив данных'!G55+'Массив данных'!K55),"") -> 15.295 | F10: =IF(ISNUMBER('Массив данных'!G55),'Массив данных'!G55,"") -> 15.73 | G10: =IF(AND(ISNUMBER('Массив данных'!K55),ISNUMBER('Массив данных'!Q55)),0.5*('Массив данных'!K55+'Массив данных'!Q55),"") -> 14.795 | H10: =IF(AND(ISNUMBER('Массив данных'!L55),ISNUMBER('Массив данных'!N55),ISNUMBER('Массив данных'!P55),ISNUMBER('Массив данных'!R55)),MAX('Массив данных'!L55,'Массив данных'!N55,'Массив данных'!P55,'Массив данных'!R55),"") -> 15.31
A11: 6 | B11: 1991 | C11: =IF(AND(ISNUMBER('Массив данных'!C56),ISNUMBER('Массив данных'!G56)),0.5*('Массив данных'!C56+'Массив данных'!G56),"") -> 16.385 | D11: =IF(ISNUMBER('Массив данных'!D56),'Массив данных'!D56,"") -> 22.57 | E11: =IF(AND(ISNUMBER('Массив данных'!G56),ISNUMBER('Массив данных'!K56)),0.5*('Массив данных'!G56+'Массив данных'!K56),"") -> 15.235 | F11: =IF(ISNUMBER('Массив данных'!G56),'Массив данных'!G56,"") -> 15.68 | G11: =IF(AND(ISNUMBER('Массив данных'!K56),ISNUMBER('Массив данных'!Q56)),0.5*('Массив данных'!K56+'Массив данных'!Q56),"") -> 14.72 | H11: =IF(AND(ISNUMBER('Массив данных'!L56),ISNUMBER('Массив данных'!N56),ISNUMBER('Массив данных'!P56),ISNUMBER('Массив данных'!R56)),MAX('Массив данных'!L56,'Массив данных'!N56,'Массив данных'!P56,'Массив данных'!R56),"") -> 16.04
A12: 7 | B12: 1992 | C12: =IF(AND(ISNUMBER('Массив данных'!C57),ISNUMBER('Массив данных'!G57)),0.5*('Массив данных'!C57+'Массив данных'!G57),"") -> 15.975 | D12: =IF(ISNUMBER('Массив данных'!D57),'Массив данных'!D57,"") -> 20.61 | E12: =IF(AND(ISNUMBER('Массив данных'!G57),ISNUMBER('Массив данных'!K57)),0.5*('Массив данных'!G57+'Массив данных'!K57),"") -> 15.085 | F12: =IF(ISNUMBER('Массив данных'!G57),'Массив данных'!G57,"") -> 15.4 | G12: =IF(AND(ISNUMBER('Массив данных'!K57),ISNUMBER('Массив данных'!Q57)),0.5*('Массив данных'!K57+'Массив данных'!Q57),"") -> 14.72 | H12: =IF(AND(ISNUMBER('Массив данных'!L57),ISNUMBER('Массив данных'!N57),ISNUMBER('Массив данных'!P57),ISNUMBER('Массив данных'!R57)),MAX('Массив данных'!L57,'Массив данных'!N57,'Массив данных'!P57,'Массив данных'!R57),"") -> 15.21
A13: 8 | B13: 1993 | C13: =IF(AND(ISNUMBER('Массив данных'!C58),ISNUMBER('Массив данных'!G58)),0.5*('Массив данных'!C58+'Массив данных'!G58),"") -> 16.07 | D13: =IF(ISNUMBER('Массив данных'!D58),'Массив данных'!D58,"") -> 20.55 | E13: =IF(AND(ISNUMBER('Массив данных'!G58),ISNUMBER('Массив данных'!K58)),0.5*('Массив данных'!G58+'Массив данных'!K58),"") -> 15.06 | F13: =IF(ISNUMBER('Массив данных'!G58),'Массив данных'!G58,"") -> 15.43 | G13: =IF(AND(ISNUMBER('Массив данных'!K58),ISNUMBER('Массив данных'!Q58)),0.5*('Массив данных'!K58+'Массив данных'!Q58),"") -> 14.635 | H13: =IF(AND(ISNUMBER('Массив данных'!L58),ISNUMBER('Массив данных'!N58),ISNUMBER('Массив данных'!P58),ISNUMBER('Массив данных'!R58)),MAX('Массив данных'!L58,'Массив данных'!N58,'Массив данных'!P58,'Массив данных'!R58),"") -> 15.22
A14: 9 | B14: 1994 | C14: =IF(AND(ISNUMBER('Массив данных'!C59),ISNUMBER('Массив данных'!G59)),0.5*('Массив данных'!C59+'Массив данных'!G59),"") -> 16.545 | D14: =IF(ISNUMBER('Массив данных'!D59),'Массив данных'!D59,"") -> 21.7 | E14: =IF(AND(ISNUMBER('Массив данных'!G59),ISNUMBER('Массив данных'!K59)),0.5*('Массив данных'!G59+'Массив данных'!K59),"") -> 15.225 | F14: =IF(ISNUMBER('Массив данных'!G59),'Массив данных'!G59,"") -> 15.71 | G14: =IF(AND(ISNUMBER('Массив данных'!K59),ISNUMBER('Массив данных'!Q59)),0.5*('Массив данных'!K59+'Массив данных'!Q59),"") -> 14.655 | H14: =IF(AND(ISNUMBER('Массив данных'!L59),ISNUMBER('Массив данных'!N59),ISNUMBER('Массив данных'!P59),ISNUMBER('Массив данных'!R59)),MAX('Массив данных'!L59,'Массив данных'!N59,'Массив данных'!P59,'Массив данных'!R59),"") -> 15.34
A15: 10 | B15: 1995 | C15: =IF(AND(ISNUMBER('Массив данных'!C60),ISNUMBER('Массив данных'!G60)),0.5*('Массив данных'!C60+'Массив данных'!G60),"") -> 16.125 | D15: =IF(ISNUMBER('Массив данных'!D60),'Массив данных'!D60,"") -> 21.93 | E15: =IF(AND(ISNUMBER('Массив данных'!G60),ISNUMBER('Массив данных'!K60)),0.5*('Массив данных'!G60+'Массив данных'!K60),"") -> 15.175 | F15: =IF(ISNUMBER('Массив данных'!G60),'Массив данных'!G60,"") -> 15.54 | G15: =IF(AND(ISNUMBER('Массив данных'!K60),ISNUMBER('Массив данных'!Q60)),0.5*('Массив данных'!K60+'Массив данных'!Q60),"") -> 14.75 | H15: =IF(AND(ISNUMBER('Массив данных'!L60),ISNUMBER('Массив данных'!N60),ISNUMBER('Массив данных'!P60),ISNUMBER('Массив данных'!R60)),MAX('Массив данных'!L60,'Массив данных'!N60,'Массив данных'!P60,'Массив данных'!R60),"") -> 15.58
A16: 11 | B16: 1996 | C16: =IF(AND(ISNUMBER('Массив данных'!C61),ISNUMBER('Массив данных'!G61)),0.5*('Массив данных'!C61+'Массив данных'!G61),"") -> 15.235 | D16: =IF(ISNUMBER('Массив данных'!D61),'Массив данных'!D61,"") -> 19.65 | E16: =IF(AND(ISNUMBER('Массив данных'!G61),ISNUMBER('Массив данных'!K61)),0.5*('Массив данных'!G61+'Массив данных'!K61),"") -> 14.705 | F16: =IF(ISNUMBER('Массив данных'!G61),'Массив данных'!G61,"") -> 14.87 | G16: =IF(AND(ISNUMBER('Массив данных'!K61),ISNUMBER('Массив данных'!Q61)),0.5*('Массив данных'!K61+'Массив данных'!Q61),"") -> 14.525 | H16: =IF(AND(ISNUMBER('Массив данных'!L61),ISNUMBER('Массив данных'!N61),ISNUMBER('Массив данных'!P61),ISNUMBER('Массив данных'!R61)),MAX('Массив данных'!L61,'Массив данных'!N61,'Массив данных'!P61,'Массив данных'!R61),"") -> 15.28
A17: 12 | B17: 1997 | C17: =IF(AND(ISNUMBER('Массив данных'!C62),ISNUMBER('Массив данных'!G62)),0.5*('Массив данных'!C62+'Массив данных'!G62),"") -> 15.78 | D17: =IF(ISNUMBER('Массив данных'!D62),'Массив данных'!D62,"") -> 20.96 | E17: =IF(AND(ISNUMBER('Массив данных'!G62),ISNUMBER('Массив данных'!K62)),0.5*('Массив данных'!G62+'Массив данных'!K62),"") -> 15.02 | F17: =IF(ISNUMBER('Массив данных'!G62),'Массив данных'!G62,"") -> 15.31 | G17: =IF(AND(ISNUMBER('Массив данных'!K62),ISNUMBER('Массив данных'!Q62)),0.5*('Массив данных'!K62+'Массив данных'!Q62),"") -> 14.685 | H17: =IF(AND(ISNUMBER('Массив данных'!L62),ISNUMBER('Массив данных'!N62),ISNUMBER('Массив данных'!P62),ISNUMBER('Массив данных'!R62)),MAX('Массив данных'!L62,'Массив данных'!N62,'Массив данных'!P62,'Массив данных'!R62),"") -> 15.5
... A36: 31 | B36: 2016 | C36: =IF(AND(ISNUMBER('Массив данных'!C81),ISNUMBER('Массив данных'!G81)),0.5*('Массив данных'!C81+'Массив данных'!G81),"") -> 15.94 | D36: =IF(ISNUMBER('Массив данных'!D81),'Массив данных'!D81,"") -> 21.68 | E36: =IF(AND(ISNUMBER('Массив данных'!G81),ISNUMBER('Массив данных'!K81)),0.5*('Массив данных'!G81+'Массив данных'!K81),"") -> 15.135 | F36: =IF(ISNUMBER('Массив данных'!G81),'Массив данных'!G81,"") -> 15.43 | G36: =IF(AND(ISNUMBER('Массив данных'!K81),ISNUMBER('Массив данных'!Q81)),0.5*('Массив данных'!K81+'Массив данных'!Q81),"") -> 14.785 | H36: =IF(AND(ISNUMBER('Массив данных'!L81),ISNUMBER('Массив данных'!N81),ISNUMBER('Массив данных'!P81),ISNUMBER('Массив данных'!R81)),MAX('Массив данных'!L81,'Массив данных'!N81,'Массив данных'!P81,'Массив данных'!R81),"") -> 15.6
A37: 32 | B37: 2017 | C37: =IF(AND(ISNUMBER('Массив данных'!C82),ISNUMBER('Массив данных'!G82)),0.5*('Массив данных'!C82+'Массив данных'!G82),"") -> 16.055 | D37: =IF(ISNUMBER('Массив данных'!D82),'Массив данных'!D82,"") -> 20.72 | E37: =IF(AND(ISNUMBER('Массив данных'!G82),ISNUMBER('Массив данных'!K82)),0.5*('Массив данных'!G82+'Массив данных'!K82),"") -> 15.19 | F37: =IF(ISNUMBER('Массив данных'!G82),'Массив данных'!G82,"") -> 15.54 | G37: =IF(AND(ISNUMBER('Массив данных'!K82),ISNUMBER('Массив данных'!Q82)),0.5*('Массив данных'!K82+'Массив данных'!Q82),"") -> 14.78 | H37: =IF(AND(ISNUMBER('Массив данных'!L82),ISNUMBER('Массив данных'!N82),ISNUMBER('Массив данных'!P82),ISNUMBER('Массив данных'!R82)),MAX('Массив данных'!L82,'Массив данных'!N82,'Массив данных'!P82,'Массив данных'!R82),"") -> 15.45 | J37: 2. Средний (Озерно-речной) участок Волгоградского вдхр (Маркс - Ровное):
A38: 33 | B38: 2018 | C38: =IF(AND(ISNUMBER('Массив данных'!C83),ISNUMBER('Массив данных'!G83)),0.5*('Массив данных'!C83+'Массив данных'!G83),"") -> 15.845 | D38: =IF(ISNUMBER('Массив данных'!D83),'Массив данных'!D83,"") -> 21.38 | E38: =IF(AND(ISNUMBER('Массив данных'!G83),ISNUMBER('Массив данных'!K83)),0.5*('Массив данных'!G83+'Массив данных'!K83),"") -> 14.96 | F38: =IF(ISNUMBER('Массив данных'!G83),'Массив данных'!G83,"") -> 15.22 | G38: =IF(AND(ISNUMBER('Массив данных'!K83),ISNUMBER('Массив данных'!Q83)),0.5*('Массив данных'!K83+'Массив данных'!Q83),"") -> 14.64 | H38: =IF(AND(ISNUMBER('Массив данных'!L83),ISNUMBER('Массив данных'!N83),ISNUMBER('Массив данных'!P83),ISNUMBER('Массив данных'!R83)),MAX('Массив данных'!L83,'Массив данных'!N83,'Массив данных'!P83,'Массив данных'!R83),"") -> 15.2
A39: Среднемноголетний уровень за период 1986-2018 гг. | G39: =AVERAGE(G6:G38) -> 14.670152 | H39: =AVERAGE(H6:H38) -> 15.431515
J69: 3. Нижний (Озерный) участок Волгоградского вдхр (Ровное - Волжский):
C92: Озерный участок

Sheet Лист3
